#VRML_SIM R2019a utf8
WorldInfo {
}
Viewpoint {
  orientation -0.18225137661042817 -0.969149443743221 -0.16593309319062674 1.544390152307338
  position -1.3876413357143276 2.40119122110713 -0.32430159800816466
}
TexturedBackground {
}
TexturedBackgroundLight {
}
Floor {
}
DEF G_Basedown Solid {
  translation 0.4 0.025 -0.4
  children [
    Shape {
      appearance DEF C_greenbase PBRAppearance {
        baseColor 0.5411764705882353 0.8862745098039215 0.20392156862745098
      }
      geometry Box {
        size 1 0.05 1
      }
    }
  ]
  name "solid(1)"
}
DEF G_Base2 Solid {
  translation 0.4 0.975 -0.4
  children [
    Shape {
      appearance USE C_greenbase
      geometry Box {
        size 1 0.05 1
      }
    }
  ]
  name "solid(2)"
}
DEF G_Face1 Solid {
  translation -0.05 0.05000000000000003 0.095
  children [
    DEF G_Box1 Group {
      children [
        Transform {
          translation 0 0.45 0
          children [
            Shape {
              appearance DEF C_box1 PBRAppearance {
                baseColor 0.6784313725490196 0.4980392156862745 0.6588235294117647
              }
              geometry DEF G_box1_m Box {
                size 0.1 0.9 0.01
              }
            }
          ]
        }
        Transform {
          translation 0.45000000000000023 0.85 0
          rotation 0 0 1 1.5707996938995747
          children [
            Shape {
              appearance USE C_box1
              geometry Box {
                size 0.1 0.9 0.01
              }
            }
          ]
        }
        Transform {
          translation 0.45000000000000023 0.049999999999999996 0
          rotation 0 0 1 1.5707996938995747
          children [
            Shape {
              appearance USE C_box1
              geometry Box {
                size 0.1 0.9 0.01
              }
            }
          ]
        }
        Transform {
          translation 0.9000000000000004 0.45 0
          children [
            Shape {
              appearance USE C_box1
              geometry Box {
                size 0.1 0.9 0.01
              }
            }
          ]
        }
        Transform {
          translation 0.45185983993961215 0.443914196703047 0
          rotation 0 0 1 0.85
          children [
            Shape {
              appearance USE C_box1
              geometry Box {
                size 0.07 1.2 0.01
              }
            }
          ]
        }
        Transform {
          translation 0.4454823890947886 0.44959288765413774 0
          rotation 0 0 1 -0.85
          children [
            Shape {
              appearance USE C_box1
              geometry Box {
                size 0.07 1.2 0.01
              }
            }
          ]
        }
      ]
    }
  ]
}
DEF G_Face2 Solid {
  translation -0.05 0.05000000000000003 -0.8950000000000002
  children [
    DEF G_Box1 Group {
      children [
        Transform {
          translation 0 0.45 0
          children [
            Shape {
              appearance USE C_box1
              geometry Box {
                size 0.1 0.9 0.01
              }
            }
          ]
        }
        Transform {
          translation 0.45000000000000023 0.85 0
          rotation 0 0 1 1.5707996938995747
          children [
            Shape {
              appearance USE C_box1
              geometry Box {
                size 0.1 0.9 0.01
              }
            }
          ]
        }
        Transform {
          translation 0.45000000000000023 0.049999999999999996 0
          rotation 0 0 1 1.5707996938995747
          children [
            Shape {
              appearance USE C_box1
              geometry Box {
                size 0.1 0.9 0.01
              }
            }
          ]
        }
        Transform {
          translation 0.9000000000000004 0.45 0
          children [
            Shape {
              appearance USE C_box1
              geometry Box {
                size 0.1 0.9 0.01
              }
            }
          ]
        }
        Transform {
          translation 0.45185983993961215 0.443914196703047 0
          rotation 0 0 1 0.85
          children [
            Shape {
              appearance USE C_box1
              geometry Box {
                size 0.07 1.2 0.01
              }
            }
          ]
        }
        Transform {
          translation 0.4454823890947886 0.44959288765413774 0
          rotation 0 0 1 -0.85
          children [
            Shape {
              appearance USE C_box1
              geometry Box {
                size 0.07 1.2 0.01
              }
            }
          ]
        }
      ]
    }
  ]
  name "solid(3)"
}
DEF G_Face3 Solid {
  translation 0.895 0.05000000000000003 0.05499645841839673
  rotation 0 1 0 1.5708003061004252
  children [
    DEF G_Box3 Group {
      children [
        Transform {
          translation 0 0.45 0
          children [
            Shape {
              appearance DEF C_BOX3 PBRAppearance {
                baseColor 0.9294117647058824 0.8313725490196079 0
              }
              geometry Box {
                size 0.1 0.9 0.01
              }
            }
          ]
        }
        Transform {
          translation 0.45000000000000023 0.85 0
          rotation 0 0 1 1.5707996938995747
          children [
            Shape {
              appearance USE C_BOX3
              geometry Box {
                size 0.1 0.9 0.01
              }
            }
          ]
        }
        Transform {
          translation 0.45000000000000023 0.049999999999999996 0
          rotation 0 0 1 1.5707996938995747
          children [
            Shape {
              appearance USE C_BOX3
              geometry Box {
                size 0.1 0.9 0.01
              }
            }
          ]
        }
        Transform {
          translation 0.9000000000000004 0.45 0
          children [
            Shape {
              appearance USE C_BOX3
              geometry Box {
                size 0.1 0.9 0.01
              }
            }
          ]
        }
        Transform {
          translation 0.45185983993961215 0.443914196703047 0
          rotation 0 0 1 0.85
          children [
            Shape {
              appearance USE C_BOX3
              geometry Box {
                size 0.07 1.2 0.01
              }
            }
          ]
        }
        Transform {
          translation 0.4454823890947886 0.44959288765413774 0
          rotation 0 0 1 -0.85
          children [
            Shape {
              appearance USE C_BOX3
              geometry Box {
                size 0.07 1.2 0.01
              }
            }
          ]
        }
      ]
    }
  ]
  name "solid(5)"
}
DEF G_Face4 Solid {
  translation -0.095 0.05000000000000003 0.05500015917253832
  rotation 0 1 0 1.5708003061004252
  children [
    DEF G_Box3 Group {
      children [
        Transform {
          translation 0 0.45 0
          children [
            Shape {
              appearance USE C_BOX3
              geometry Box {
                size 0.1 0.9 0.01
              }
            }
          ]
        }
        Transform {
          translation 0.45000000000000023 0.85 0
          rotation 0 0 1 1.5707996938995747
          children [
            Shape {
              appearance USE C_BOX3
              geometry Box {
                size 0.1 0.9 0.01
              }
            }
          ]
        }
        Transform {
          translation 0.45000000000000023 0.049999999999999996 0
          rotation 0 0 1 1.5707996938995747
          children [
            Shape {
              appearance USE C_BOX3
              geometry Box {
                size 0.1 0.9 0.01
              }
            }
          ]
        }
        Transform {
          translation 0.9000000000000004 0.45 0
          children [
            Shape {
              appearance USE C_BOX3
              geometry Box {
                size 0.1 0.9 0.01
              }
            }
          ]
        }
        Transform {
          translation 0.45185983993961215 0.443914196703047 0
          rotation 0 0 1 0.85
          children [
            Shape {
              appearance USE C_BOX3
              geometry Box {
                size 0.07 1.2 0.01
              }
            }
          ]
        }
        Transform {
          translation 0.4454823890947886 0.44959288765413774 0
          rotation 0 0 1 -0.85
          children [
            Shape {
              appearance USE C_BOX3
              geometry Box {
                size 0.07 1.2 0.01
              }
            }
          ]
        }
      ]
    }
  ]
  name "solid(4)"
}
Solid {
  translation 0.45 1.5 -0.3899999999999999
  children [
    Shape {
      geometry Cylinder {
        height 1
        radius 0.15
      }
    }
    HingeJoint {
      jointParameters HingeJointParameters {
        axis 0 1 0
        anchor 0 0.15 0
      }
      endPoint Solid {
        translation 0 0.55 0.25
        rotation 1 0 0 1.5707996938995747
        children [
          Shape {
            appearance PBRAppearance {
            }
            geometry DEF G_Cyl2 Cylinder {
              height 0.5
              radius 0.05
            }
          }
        ]
        boundingObject USE G_Cyl2
        physics Physics {
        }
      }
    }
  ]
  name "solid(6)"
}
